2020-07-28 11:59:09,752 ERROR: Exception on /index [POST] [in e:\documents\python\micro_blog\venv\lib\site-packages\flask\app.py:1891]
Traceback (most recent call last):
  File "e:\documents\python\micro_blog\venv\lib\site-packages\flask\app.py", line 2447, in wsgi_app
    response = self.full_dispatch_request()
  File "e:\documents\python\micro_blog\venv\lib\site-packages\flask\app.py", line 1952, in full_dispatch_request
    rv = self.handle_user_exception(e)
  File "e:\documents\python\micro_blog\venv\lib\site-packages\flask\app.py", line 1821, in handle_user_exception
    reraise(exc_type, exc_value, tb)
  File "e:\documents\python\micro_blog\venv\lib\site-packages\flask\_compat.py", line 39, in reraise
    raise value
  File "e:\documents\python\micro_blog\venv\lib\site-packages\flask\app.py", line 1950, in full_dispatch_request
    rv = self.dispatch_request()
  File "e:\documents\python\micro_blog\venv\lib\site-packages\flask\app.py", line 1936, in dispatch_request
    return self.view_functions[rule.endpoint](**req.view_args)
  File "e:\documents\python\micro_blog\venv\lib\site-packages\flask_login\utils.py", line 272, in decorated_view
    return func(*args, **kwargs)
  File "E:\Documents\Python\micro_blog\app\routes.py", line 22, in index
    post = Post(body=form.post.date, author=current_user)
AttributeError: 'TextAreaField' object has no attribute 'date'
2020-07-28 11:59:36,588 INFO: Microblog startup [in E:\Documents\Python\micro_blog\app\__init__.py:43]
2020-07-28 12:00:37,255 INFO: Microblog startup [in E:\Documents\Python\micro_blog\app\__init__.py:43]
2020-07-28 12:06:11,107 INFO: Microblog startup [in E:\Documents\Python\micro_blog\app\__init__.py:43]
2020-07-28 12:06:13,558 ERROR: Exception on /index [GET] [in e:\documents\python\micro_blog\venv\lib\site-packages\flask\app.py:1891]
Traceback (most recent call last):
  File "e:\documents\python\micro_blog\venv\lib\site-packages\flask\app.py", line 2447, in wsgi_app
    response = self.full_dispatch_request()
  File "e:\documents\python\micro_blog\venv\lib\site-packages\flask\app.py", line 1952, in full_dispatch_request
    rv = self.handle_user_exception(e)
  File "e:\documents\python\micro_blog\venv\lib\site-packages\flask\app.py", line 1821, in handle_user_exception
    reraise(exc_type, exc_value, tb)
  File "e:\documents\python\micro_blog\venv\lib\site-packages\flask\_compat.py", line 39, in reraise
    raise value
  File "e:\documents\python\micro_blog\venv\lib\site-packages\flask\app.py", line 1950, in full_dispatch_request
    rv = self.dispatch_request()
  File "e:\documents\python\micro_blog\venv\lib\site-packages\flask\app.py", line 1936, in dispatch_request
    return self.view_functions[rule.endpoint](**req.view_args)
  File "e:\documents\python\micro_blog\venv\lib\site-packages\flask_login\utils.py", line 272, in decorated_view
    return func(*args, **kwargs)
  File "E:\Documents\Python\micro_blog\app\routes.py", line 29, in index
    return render_template('index.html', title='Home', form=form, posts=posts)
  File "e:\documents\python\micro_blog\venv\lib\site-packages\flask\templating.py", line 137, in render_template
    return _render(
  File "e:\documents\python\micro_blog\venv\lib\site-packages\flask\templating.py", line 120, in _render
    rv = template.render(context)
  File "e:\documents\python\micro_blog\venv\lib\site-packages\jinja2\environment.py", line 1090, in render
    self.environment.handle_exception()
  File "e:\documents\python\micro_blog\venv\lib\site-packages\jinja2\environment.py", line 832, in handle_exception
    reraise(*rewrite_traceback_stack(source=source))
  File "e:\documents\python\micro_blog\venv\lib\site-packages\jinja2\_compat.py", line 28, in reraise
    raise value.with_traceback(tb)
  File "E:\Documents\Python\micro_blog\app\templates\index.html", line 1, in top-level template code
    {% extends "base.html" %}
  File "E:\Documents\Python\micro_blog\app\templates\base.html", line 36, in top-level template code
    {% block content %} {% endblock %}
  File "E:\Documents\Python\micro_blog\app\templates\index.html", line 21, in block "content"
    {% include "_post.html" %}
  File "e:\documents\python\micro_blog\venv\lib\site-packages\jinja2\environment.py", line 832, in handle_exception
    reraise(*rewrite_traceback_stack(source=source))
  File "e:\documents\python\micro_blog\venv\lib\site-packages\jinja2\_compat.py", line 28, in reraise
    raise value.with_traceback(tb)
  File "E:\Documents\Python\micro_blog\app\templates\_post.html", line 4, in template
    <td><a href="{{ url_for('user', username=post.author.username }}">{{ post.author.username }}</a> says: <b>{{ post.body }}</b></td>
jinja2.exceptions.TemplateSyntaxError: unexpected '}', expected ')'
2020-07-28 12:06:36,038 INFO: Microblog startup [in E:\Documents\Python\micro_blog\app\__init__.py:43]
2020-07-28 12:14:58,661 INFO: Microblog startup [in E:\Documents\Python\micro_blog\app\__init__.py:43]
2020-07-28 12:20:31,388 INFO: Microblog startup [in E:\Documents\Python\micro_blog\app\__init__.py:43]
2020-07-28 12:21:04,700 INFO: Microblog startup [in E:\Documents\Python\micro_blog\app\__init__.py:43]
2020-07-28 12:24:52,135 INFO: Microblog startup [in E:\Documents\Python\micro_blog\app\__init__.py:43]
