2020-07-28 17:58:38,581 ERROR: Exception on /reset_password_request [POST] [in e:\documents\python\micro_blog\venv\lib\site-packages\flask\app.py:1891]
Traceback (most recent call last):
  File "e:\documents\python\micro_blog\venv\lib\site-packages\flask\app.py", line 2447, in wsgi_app
    response = self.full_dispatch_request()
  File "e:\documents\python\micro_blog\venv\lib\site-packages\flask\app.py", line 1952, in full_dispatch_request
    rv = self.handle_user_exception(e)
  File "e:\documents\python\micro_blog\venv\lib\site-packages\flask\app.py", line 1821, in handle_user_exception
    reraise(exc_type, exc_value, tb)
  File "e:\documents\python\micro_blog\venv\lib\site-packages\flask\_compat.py", line 39, in reraise
    raise value
  File "e:\documents\python\micro_blog\venv\lib\site-packages\flask\app.py", line 1950, in full_dispatch_request
    rv = self.dispatch_request()
  File "e:\documents\python\micro_blog\venv\lib\site-packages\flask\app.py", line 1936, in dispatch_request
    return self.view_functions[rule.endpoint](**req.view_args)
  File "E:\Documents\Python\micro_blog\app\routes.py", line 159, in reset_password_request
    send_password_reset_email(user)
  File "E:\Documents\Python\micro_blog\app\email.py", line 21, in send_password_reset_email
    text_body=render_template('email/reset_password.txt', user=user, token=token),
  File "e:\documents\python\micro_blog\venv\lib\site-packages\flask\templating.py", line 137, in render_template
    return _render(
  File "e:\documents\python\micro_blog\venv\lib\site-packages\flask\templating.py", line 120, in _render
    rv = template.render(context)
  File "e:\documents\python\micro_blog\venv\lib\site-packages\jinja2\environment.py", line 1090, in render
    self.environment.handle_exception()
  File "e:\documents\python\micro_blog\venv\lib\site-packages\jinja2\environment.py", line 832, in handle_exception
    reraise(*rewrite_traceback_stack(source=source))
  File "e:\documents\python\micro_blog\venv\lib\site-packages\jinja2\_compat.py", line 28, in reraise
    raise value.with_traceback(tb)
  File "E:\Documents\Python\micro_blog\app\templates\email\reset_password.txt", line 5, in top-level template code
    {{ url_for('reset_password', token=token, _external=True) }}
  File "e:\documents\python\micro_blog\venv\lib\site-packages\flask\helpers.py", line 370, in url_for
    return appctx.app.handle_url_build_error(error, endpoint, values)
  File "e:\documents\python\micro_blog\venv\lib\site-packages\flask\app.py", line 2216, in handle_url_build_error
    reraise(exc_type, exc_value, tb)
  File "e:\documents\python\micro_blog\venv\lib\site-packages\flask\_compat.py", line 39, in reraise
    raise value
  File "e:\documents\python\micro_blog\venv\lib\site-packages\flask\helpers.py", line 357, in url_for
    rv = url_adapter.build(
  File "e:\documents\python\micro_blog\venv\lib\site-packages\werkzeug\routing.py", line 2179, in build
    raise BuildError(endpoint, values, method, self)
werkzeug.routing.BuildError: Could not build url for endpoint 'reset_password' with values ['token']. Did you mean 'reset_password_request' instead?
2020-07-28 23:04:01,908 INFO: Microblog startup [in E:\Documents\Python\micro_blog\app\__init__.py:52]
2020-07-28 23:04:31,463 INFO: Microblog startup [in E:\Documents\Python\micro_blog\app\__init__.py:52]
